#VRML_SIM R2019b utf8
WorldInfo {
  basicTimeStep 16
  lineScale 0.4
}
Viewpoint {
  orientation 0.6314718812252486 -0.7173316711822159 -0.2944121885058005 5.151528386128492
  position 1.386384756369837 2.5776689786245415 1.3092657503040714
}
TexturedBackground {
}
TexturedBackgroundLight {
}
Floor {
  appearance ThreadMetalPlate {
    textureTransform TextureTransform {
      scale 0.25 0.25
    }
    IBLStrength 2
  }
}
Robot {
  children [
    Display {
    }
    SolidBox {
      translation 0 0.0196501 0
      size 0.5 0.05 0.5
      appearance GalvanizedMetal {
      }
      physics Physics {
        density -1
        mass 30
      }
    }
    Solid {
      translation -1.9387072593285345e-08 0.5899282148853098 1.053124190219903e-05
      rotation -0.9903787191191333 -0.08197636950255018 -0.111489315896754 1.1015753986118597e-05
      children [
        DEF ROBOT_SHAPE Shape {
          appearance GalvanizedMetal {
            colorOverride 0.376471 0.415686 0.46274499999999996
            IBLStrength 4
          }
          geometry Box {
            size 0.1 1.1 0.15
          }
        }
        DEF HIP HingeJoint {
          jointParameters HingeJointParameters {
            position 1.125390932646287
            anchor 0 0.53 0
          }
          device [
            PositionSensor {
            }
            RotationalMotor {
              name "motor_1"
              controlPID 5 0 0
              maxVelocity 1
            }
          ]
          endPoint DEF THIGH_BB Solid {
            translation 0.05999980000000001 0.65268257316405 0.2406981310476829
            rotation -0.9999999999995007 -9.989759761094364e-07 2.5596598476218958e-08 5.158397363371017
            children [
              Shape {
                appearance BrushedAluminium {
                  textureTransform TextureTransform {
                  }
                  IBLStrength 3
                }
                geometry DEF THIGH_BOX Box {
                  size 0.02 0.6 0.07
                }
              }
              DEF HIP_2 HingeJoint {
                jointParameters HingeJointParameters {
                  position 0.28148959594895784
                  anchor 0 0.25 0
                }
                device [
                  RotationalMotor {
                    name "motor_2"
                    controlPID 1 0 0
                    maxVelocity 1
                    maxTorque 5
                  }
                  PositionSensor {
                    name "position sensor 2"
                  }
                ]
                endPoint DEF THIGH_BB_2 Solid {
                  translation 0.024999899999999617 0.4988726736769943 -0.023709424326692458
                  rotation -0.999999999992837 3.391408221122831e-06 -1.6806419829423668e-06 0.10292302678289568
                  children [
                    Shape {
                      appearance BrushedAluminium {
                      }
                      geometry DEF THIGH_BOX_2 Box {
                        size 0.02 0.6 0.07
                      }
                    }
                  ]
                  boundingObject USE THIGH_BOX_2
                  physics Physics {
                    density -1
                    mass 0.2
                    centerOfMass [
                      0 0 0
                    ]
                  }
                }
              }
            ]
            boundingObject USE THIGH_BOX
            physics Physics {
              density -1
              mass 0.2
              centerOfMass [
                0 0 0
              ]
            }
            rotationStep 0.261799
          }
        }
      ]
      boundingObject USE ROBOT_SHAPE
      physics Physics {
        density -1
        mass 1
      }
    }
  ]
  contactMaterial "basis_robot"
  controller "rob2gdl"
}
